// what is the output? and explain why?

// 1
Promise.resolve(1)
  .then(res => {
    console.log(res);
    return 2;
  })
  .catch(err => {
    return 3;
  })
  .then(res => {
    console.log(res);
  });
  
// 1 2
// 1 is resolve, then print, then 2 is returned, and no err, so 2 is printed.
// // 2
Promise.reject(1)
  .then(res => {
    console.log(res);
    return 2;
  })
  .catch(err => {
    console.log(err);
    return 3;
  })
  .then(res => {
    console.log(res);
  });
  // 1 3 
  // 1 is rejected value, and then print, and since it is rejected, is goes to ctach, so return 3 and 3 is printed

//3
function runAsync(x) {
  const p = new Promise(resolve =>
    setTimeout(() => resolve(x), 1000)
  );
  return p;
}

function runReject(x) {
  const p = new Promise((resolve, reject) =>
    setTimeout(() => reject(`Error: ${x}`), 1000 * x)
  );
  return p;
}

Promise.all([runAsync(1), runReject(4), runAsync(3), runReject(2)])
  .then(res => console.log(res))
  .catch(err => console.log(err));
// error:2
// promis all goes to then after all promis returns, and goes to catch after one error catched. Since error 2 is the first error rejected it is error 2.