// what is the output? and explain why?

// 1
Promise.resolve(1)
  .then((res) => {
    console.log(res);
    return 2;
  })
  .catch((err) => {
    return 3;
  })
  .then((res) => {
    console.log(res);
  });

// 1 2
// console.log(res); prints "1".
// Returns 2, which is passed to the next .then().

// // 2
Promise.reject(1)
  .then((res) => {
    console.log(res);
    return 2;
  })
  .catch((err) => {
    console.log(err);
    return 3;
  })
  .then((res) => {
    console.log(res);
  });

// 1 3
// console.log(err); prints "1".
// console.log(res); prints "3"

//3
function runAsync(x) {
  const p = new Promise((resolve) => setTimeout(() => resolve(x), 1000));
  return p;
}

function runReject(x) {
  const p = new Promise((resolve, reject) =>
    setTimeout(() => reject(`Error: ${x}`), 1000 * x)
  );
  return p;
}

Promise.all([runAsync(1), runReject(4), runAsync(3), runReject(2)])
  .then((res) => console.log(res))
  .catch((err) => console.log(err));

// Error : 2
// runAsync(1) resolves after 1 second.
// First rejection occurs at runReject(2), after 2 seconds.
