// what is the output? and explain why?

// 1
Promise.resolve(1)
  .then(res => {
    console.log(res);
    return 2;
  })
  .catch(err => {
    return 3;
  })
  .then(res => {
    console.log(res);
  });
  // 1
  // 2
// The output is 1 2 because the first then method is called with the resolved value 1, and the second then method is called with the returned value 2.

// // 2
Promise.reject(1)
  .then(res => {
    console.log(res);
    return 2;
  })
  .catch(err => {
    console.log(err);
    return 3;
  })
  .then(res => {
    console.log(res);
  });
  // 1
  // 3
// The output is 1 3 because the catch method is called with the rejected value 1, and the then method is called with the returned value 3.

//3
function runAsync(x) {
  const p = new Promise(resolve =>
    setTimeout(() => resolve(x), 1000)
  );
  return p;
}

function runReject(x) {
  const p = new Promise((resolve, reject) =>
    setTimeout(() => reject(`Error: ${x}`), 1000 * x)
  );
  return p;
}

Promise.all([runAsync(1), runReject(4), runAsync(3), runReject(2)])
  .then(res => console.log(res))
  .catch(err => console.log(err));
  // Error: 4
// The output is Error: 4 because the Promise.all method rejects the promise with the rejected value 4.

