// what is the output? and explain why?

// 1
Promise.resolve(1)
  .then(res => {
    console.log(res);
    return 2;
  })
  .catch(err => {
    return 3;
  })
  .then(res => {
    console.log(res);
  });
  // 1, 2
  // first res is 1, returns 2, and second res is 2

// // 2
Promise.reject(1)
  .then(res => {
    console.log(res);
    return 2;
  })
  .catch(err => {
    console.log(err);
    return 3;
  })
  .then(res => {
    console.log(res);
  });
  // 1,3
  // first res is 1, but it catches an error, and returns 3, the second res is 3

//3
function runAsync(x) {
  const p = new Promise(resolve =>
    setTimeout(() => resolve(x), 1000)
  );
  return p;
}

function runReject(x) {
  const p = new Promise((resolve, reject) =>
    setTimeout(() => reject(`Error: ${x}`), 1000 * x)
  );
  return p;
}

Promise.all([runAsync(1), runReject(4), runAsync(3), runReject(2)])
  .then(res => console.log(res))
  .catch(err => console.log(err));
   // Error: 2
   // becasue .all() requires all to be fullfilled w/o rejection, the earliest rejection will be 1000*2
